Workbook

Sheet 总览看板
A1: 动态学习计划总览看板
A3: 目标 | B3: [具体目标] | J3: 总进度 | K3: =IFERROR((COUNTIF('周计划明细'!$H$2:$H$200,"25%")*0.25+COUNTIF('周计划明细'!$H$2:$H$200,"50%")*0.5+COUNTIF('周计划明细'!$H$2:$H$200,"75%")*0.75+COUNTIF('周计划明细'!$H$2:$H$200,"100%"))/MAX(1,COUNTA('周计划明细'!$A$2:$A$200)),0)
A4: 可用总时长 | B4: [X小时/周] | J4: 进度条 | K4: =REPT("|",ROUND(K3*20,0))&REPT(".",20-ROUND(K3*20,0))
A5: 注意力集中时长 | B5: [25分钟番茄钟 / 90分钟深度学习] | J5: 已完成天数 | K5: =COUNTIF('周计划明细'!$H$2:$H$200,"100%")
A6: 学习风格 | B6: [视觉型 / 听觉型 / 动手实践型 / 阅读型] | J6: 知识点精通率 | K6: =IFERROR(COUNTIF('知识点追踪'!$D$2:$D$200,"精通")/MAX(1,COUNTA('知识点追踪'!$B$2:$B$200)),0)
A8: 阶段 | B8: 时间节点 | C8: 核心模块 | D8: 里程碑 | E8: 验收标准 | F8: 当前状态 | G8: 阶段进度 | I8: 模块 | J8: 计划投入(h) | K8: 占比
A9: 阶段1 启动 | B9: 第1-2周 | C9: 基础理论 | D9: 完成知识框架搭建 | E9: 能复述核心概念并完成基础题 80% | F9: 进行中 | G9: =IF(F9="已完成",1,IF(F9="进行中",0.5,0)) | I9: 基础理论 | J9: =SUMIF(统计源!$C$2:$C$800,I9,统计源!$D$2:$D$800) | K9: =IFERROR(J9/SUM($J$9:$J$13),0)
A10: 阶段2 强化 | B10: 第3-6周 | C10: 核心技能 | D10: 完成重点模块训练 | E10: 能独立完成综合练习并输出错题清单 | F10: 未开始 | G10: =IF(F10="已完成",1,IF(F10="进行中",0.5,0)) | I10: 核心技能 | J10: =SUMIF(统计源!$C$2:$C$800,I10,统计源!$D$2:$D$800) | K10: =IFERROR(J10/SUM($J$9:$J$13),0)
A11: 阶段3 输出 | B11: 第7-8周 | C11: 实战应用 | D11: 完成项目/模拟考/复盘 | E11: 达到目标分数或完成项目交付 | F11: 未开始 | G11: =IF(F11="已完成",1,IF(F11="进行中",0.5,0)) | I11: 实战应用 | J11: =SUMIF(统计源!$C$2:$C$800,I11,统计源!$D$2:$D$800) | K11: =IFERROR(J11/SUM($J$9:$J$13),0)
I12: 复盘输出 | J12: =SUMIF(统计源!$C$2:$C$800,I12,统计源!$D$2:$D$800) | K12: =IFERROR(J12/SUM($J$9:$J$13),0)
I13: 机动调整 | J13: =SUMIF(统计源!$C$2:$C$800,I13,统计源!$D$2:$D$800) | K13: =IFERROR(J13/SUM($J$9:$J$13),0)
A15: 调整日期 | B15: 变更内容 | C15: 变更原因 | D15: 影响范围 | E15: 应对措施
A16: 46230 | B16: 晚间学习改为错题复盘 | C16: 连续两天注意力下降 | D16: 晚间时段 | E16: 将重内容前移到上午
A17: 46237 | B17: 周末增加 2 小时机动时段 | C17: 阶段测验暴露薄弱点 | D17: 周末计划 | E17: 补强化练习与复盘

Sheet 周计划明细
A1: 周次 | B1: 日期 | C1: 星期 | D1: 上午内容 | E1: 下午内容 | F1: 晚上内容 | G1: 学习时长(自动求和) | H1: 完成度 | I1: 实际用时 | J1: 差异分析
A2: 1 | B2: 46223 | C2: =TEXT(B2,"aaaa") | D2: 基础理论:课程导学|1.5h | E2: 核心技能:例题拆解|1.0h | F2: 复盘输出:学习笔记|0.5h | G2: =SUM(IFERROR(VALUE(TEXTBEFORE(TEXTAFTER(D2,"|"),"h")),0),IFERROR(VALUE(TEXTBEFORE(TEXTAFTER(E2,"|"),"h")),0),IFERROR(VALUE(TEXTBEFORE(TEXTAFTER(F2,"|"),"h")),0)) | H2: 75% | I2: 1.8 | J2: =IF(OR(G2="",I2=""),"待填写",IF(I2>G2,"超时 "&TEXT(I2-G2,"0.0")&"h",IF(I2<G2,"节省 "&TEXT(G2-I2,"0.0")&"h","符合预期")))
A3: 1 | B3: 46224 | C3: =TEXT(B3,"aaaa") | D3: 核心技能:章节练习|2.0h | E3: 实战应用:案例模仿|1.0h | F3: 复盘输出:错题整理|0.5h | G3: =SUM(IFERROR(VALUE(TEXTBEFORE(TEXTAFTER(D3,"|"),"h")),0),IFERROR(VALUE(TEXTBEFORE(TEXTAFTER(E3,"|"),"h")),0),IFERROR(VALUE(TEXTBEFORE(TEXTAFTER(F3,"|"),"h")),0)) | H3: 100% | I3: 3.5 | J3: =IF(OR(G3="",I3=""),"待填写",IF(I3>G3,"超时 "&TEXT(I3-G3,"0.0")&"h",IF(I3<G3,"节省 "&TEXT(G3-I3,"0.0")&"h","符合预期")))
A4: 1 | B4: 46225 | C4: =TEXT(B4,"aaaa") | D4: 基础理论:知识回顾|1.0h | E4: 核心技能:专项训练|1.5h | F4: 机动调整:补漏复习|0.5h | G4: =SUM(IFERROR(VALUE(TEXTBEFORE(TEXTAFTER(D4,"|"),"h")),0),IFERROR(VALUE(TEXTBEFORE(TEXTAFTER(E4,"|"),"h")),0),IFERROR(VALUE(TEXTBEFORE(TEXTAFTER(F4,"|"),"h")),0)) | H4: 50% | I4: 2.2 | J4: =IF(OR(G4="",I4=""),"待填写",IF(I4>G4,"超时 "&TEXT(I4-G4,"0.0")&"h",IF(I4<G4,"节省 "&TEXT(G4-I4,"0.0")&"h","符合预期")))

Sheet 知识点追踪
A1: 模块 | B1: 知识点 | C1: 难度等级(1-5星) | D1: 掌握程度 | E1: 首次学习日期 | F1: 复习日期1 | G1: 复习日期2 | H1: 复习日期3 | I1: 关联知识点 | J1: 复习日期4 | K1: 复习日期5 | L1: 复习提醒
A2: 基础理论 | B2: 函数极限 | C2: ★★★☆☆ | D2: 熟悉 | E2: 46223 | F2: =E2+1 | G2: =E2+2 | H2: =E2+4 | I2: 导数定义 | J2: =E2+7 | K2: =E2+15 | L2: =IF(E2="","",IF(TODAY()>K2,"应进行第5次复习",IF(TODAY()>J2,"应进行第4次复习",IF(TODAY()>H2,"应进行第3次复习",IF(TODAY()>G2,"应进行第2次复习",IF(TODAY()>F2,"应进行第1次复习","未到复习日"))))))
A3: 核心技能 | B3: 题型拆解 | C3: ★★★★☆ | D3: 生疏 | E3: 46224 | F3: =E3+1 | G3: =E3+2 | H3: =E3+4 | I3: 错题归因 | J3: =E3+7 | K3: =E3+15 | L3: =IF(E3="","",IF(TODAY()>K3,"应进行第5次复习",IF(TODAY()>J3,"应进行第4次复习",IF(TODAY()>H3,"应进行第3次复习",IF(TODAY()>G3,"应进行第2次复习",IF(TODAY()>F3,"应进行第1次复习","未到复习日"))))))
A4: 实战应用 | B4: 综合案例 | C4: ★★★★★ | D4: 生疏 | E4: 46225 | F4: =E4+1 | G4: =E4+2 | H4: =E4+4 | I4: 项目复盘 | J4: =E4+7 | K4: =E4+15 | L4: =IF(E4="","",IF(TODAY()>K4,"应进行第5次复习",IF(TODAY()>J4,"应进行第4次复习",IF(TODAY()>H4,"应进行第3次复习",IF(TODAY()>G4,"应进行第2次复习",IF(TODAY()>F4,"应进行第1次复习","未到复习日"))))))

Sheet 资源清单
A1: 资源名称 | B1: 类型(书/视频/题库/文档) | C1: 对应模块 | D1: 预估耗时 | E1: 已用时长 | F1: 完成状态 | G1: 链接/位置 | H1: 质量评分
A2: 《基础课程讲义》 | B2: 书 | C2: 基础理论 | D2: 6 | E2: 2 | F2: 进行中 | G2: 本地/教材 | H2: 4.5
A3: 专项题训练营 | B3: 题库 | C3: 核心技能 | D3: 10 | E3: 4 | F3: 进行中 | G3: 在线题库 | H3: 4.8
A4: 案例拆解视频 | B4: 视频 | C4: 实战应用 | D4: 5 | E4: 0 | F4: 未开始 | G4: 网盘/课程平台 | H4: 4.2

Sheet 统计源
A1: 来源行 | B1: 时段 | C1: 模块 | D1: 计划时长
A2: 2 | B2: 上午 | C2: =IFERROR(TEXTBEFORE('周计划明细'!D2,":"),"") | D2: =IFERROR(VALUE(TEXTBEFORE(TEXTAFTER('周计划明细'!D2,"|"),"h")),0)
A3: 2 | B3: 下午 | C3: =IFERROR(TEXTBEFORE('周计划明细'!E2,":"),"") | D3: =IFERROR(VALUE(TEXTBEFORE(TEXTAFTER('周计划明细'!E2,"|"),"h")),0)
A4: 2 | B4: 晚上 | C4: =IFERROR(TEXTBEFORE('周计划明细'!F2,":"),"") | D4: =IFERROR(VALUE(TEXTBEFORE(TEXTAFTER('周计划明细'!F2,"|"),"h")),0)
A5: 3 | B5: 上午 | C5: =IFERROR(TEXTBEFORE('周计划明细'!D3,":"),"") | D5: =IFERROR(VALUE(TEXTBEFORE(TEXTAFTER('周计划明细'!D3,"|"),"h")),0)
A6: 3 | B6: 下午 | C6: =IFERROR(TEXTBEFORE('周计划明细'!E3,":"),"") | D6: =IFERROR(VALUE(TEXTBEFORE(TEXTAFTER('周计划明细'!E3,"|"),"h")),0)
A7: 3 | B7: 晚上 | C7: =IFERROR(TEXTBEFORE('周计划明细'!F3,":"),"") | D7: =IFERROR(VALUE(TEXTBEFORE(TEXTAFTER('周计划明细'!F3,"|"),"h")),0)
A8: 4 | B8: 上午 | C8: =IFERROR(TEXTBEFORE('周计划明细'!D4,":"),"") | D8: =IFERROR(VALUE(TEXTBEFORE(TEXTAFTER('周计划明细'!D4,"|"),"h")),0)
A9: 4 | B9: 下午 | C9: =IFERROR(TEXTBEFORE('周计划明细'!E4,":"),"") | D9: =IFERROR(VALUE(TEXTBEFORE(TEXTAFTER('周计划明细'!E4,"|"),"h")),0)
A10: 4 | B10: 晚上 | C10: =IFERROR(TEXTBEFORE('周计划明细'!F4,":"),"") | D10: =IFERROR(VALUE(TEXTBEFORE(TEXTAFTER('周计划明细'!F4,"|"),"h")),0)
A11: 5 | B11: 上午 | C11: =IFERROR(TEXTBEFORE('周计划明细'!D5,":"),"") | D11: =IFERROR(VALUE(TEXTBEFORE(TEXTAFTER('周计划明细'!D5,"|"),"h")),0)
A12: 5 | B12: 下午 | C12: =IFERROR(TEXTBEFORE('周计划明细'!E5,":"),"") | D12: =IFERROR(VALUE(TEXTBEFORE(TEXTAFTER('周计划明细'!E5,"|"),"h")),0)
A13: 5 | B13: 晚上 | C13: =IFERROR(TEXTBEFORE('周计划明细'!F5,":"),"") | D13: =IFERROR(VALUE(TEXTBEFORE(TEXTAFTER('周计划明细'!F5,"|"),"h")),0)
A14: 6 | B14: 上午 | C14: =IFERROR(TEXTBEFORE('周计划明细'!D6,":"),"") | D14: =IFERROR(VALUE(TEXTBEFORE(TEXTAFTER('周计划明细'!D6,"|"),"h")),0)
A15: 6 | B15: 下午 | C15: =IFERROR(TEXTBEFORE('周计划明细'!E6,":"),"") | D15: =IFERROR(VALUE(TEXTBEFORE(TEXTAFTER('周计划明细'!E6,"|"),"h")),0)
A16: 6 | B16: 晚上 | C16: =IFERROR(TEXTBEFORE('周计划明细'!F6,":"),"") | D16: =IFERROR(VALUE(TEXTBEFORE(TEXTAFTER('周计划明细'!F6,"|"),"h")),0)
A17: 7 | B17: 上午 | C17: =IFERROR(TEXTBEFORE('周计划明细'!D7,":"),"") | D17: =IFERROR(VALUE(TEXTBEFORE(TEXTAFTER('周计划明细'!D7,"|"),"h")),0)
A18: 7 | B18: 下午 | C18: =IFERROR(TEXTBEFORE('周计划明细'!E7,":"),"") | D18: =IFERROR(VALUE(TEXTBEFORE(TEXTAFTER('周计划明细'!E7,"|"),"h")),0)
A19: 7 | B19: 晚上 | C19: =IFERROR(TEXTBEFORE('周计划明细'!F7,":"),"") | D19: =IFERROR(VALUE(TEXTBEFORE(TEXTAFTER('周计划明细'!F7,"|"),"h")),0)
A20: 8 | B20: 上午 | C20: =IFERROR(TEXTBEFORE('周计划明细'!D8,":"),"") | D20: =IFERROR(VALUE(TEXTBEFORE(TEXTAFTER('周计划明细'!D8,"|"),"h")),0)
A21: 8 | B21: 下午 | C21: =IFERROR(TEXTBEFORE('周计划明细'!E8,":"),"") | D21: =IFERROR(VALUE(TEXTBEFORE(TEXTAFTER('周计划明细'!E8,"|"),"h")),0)
A22: 8 | B22: 晚上 | C22: =IFERROR(TEXTBEFORE('周计划明细'!F8,":"),"") | D22: =IFERROR(VALUE(TEXTBEFORE(TEXTAFTER('周计划明细'!F8,"|"),"h")),0)
A23: 9 | B23: 上午 | C23: =IFERROR(TEXTBEFORE('周计划明细'!D9,":"),"") | D23: =IFERROR(VALUE(TEXTBEFORE(TEXTAFTER('周计划明细'!D9,"|"),"h")),0)
A24: 9 | B24: 下午 | C24: =IFERROR(TEXTBEFORE('周计划明细'!E9,":"),"") | D24: =IFERROR(VALUE(TEXTBEFORE(TEXTAFTER('周计划明细'!E9,"|"),"h")),0)
A25: 9 | B25: 晚上 | C25: =IFERROR(TEXTBEFORE('周计划明细'!F9,":"),"") | D25: =IFERROR(VALUE(TEXTBEFORE(TEXTAFTER('周计划明细'!F9,"|"),"h")),0)
A26: 10 | B26: 上午 | C26: =IFERROR(TEXTBEFORE('周计划明细'!D10,":"),"") | D26: =IFERROR(VALUE(TEXTBEFORE(TEXTAFTER('周计划明细'!D10,"|"),"h")),0)
A27: 10 | B27: 下午 | C27: =IFERROR(TEXTBEFORE('周计划明细'!E10,":"),"") | D27: =IFERROR(VALUE(TEXTBEFORE(TEXTAFTER('周计划明细'!E10,"|"),"h")),0)
A28: 10 | B28: 晚上 | C28: =IFERROR(TEXTBEFORE('周计划明细'!F10,":"),"") | D28: =IFERROR(VALUE(TEXTBEFORE(TEXTAFTER('周计划明细'!F10,"|"),"h")),0)
A29: 11 | B29: 上午 | C29: =IFERROR(TEXTBEFORE('周计划明细'!D11,":"),"") | D29: =IFERROR(VALUE(TEXTBEFORE(TEXTAFTER('周计划明细'!D11,"|"),"h")),0)
A30: 11 | B30: 下午 | C30: =IFERROR(TEXTBEFORE('周计划明细'!E11,":"),"") | D30: =IFERROR(VALUE(TEXTBEFORE(TEXTAFTER('周计划明细'!E11,"|"),"h")),0)
A31: 11 | B31: 晚上 | C31: =IFERROR(TEXTBEFORE('周计划明细'!F11,":"),"") | D31: =IFERROR(VALUE(TEXTBEFORE(TEXTAFTER('周计划明细'!F11,"|"),"h")),0)
A32: 12 | B32: 上午 | C32: =IFERROR(TEXTBEFORE('周计划明细'!D12,":"),"") | D32: =IFERROR(VALUE(TEXTBEFORE(TEXTAFTER('周计划明细'!D12,"|"),"h")),0)
A33: 12 | B33: 下午 | C33: =IFERROR(TEXTBEFORE('周计划明细'!E12,":"),"") | D33: =IFERROR(VALUE(TEXTBEFORE(TEXTAFTER('周计划明细'!E12,"|"),"h")),0)
A34: 12 | B34: 晚上 | C34: =IFERROR(TEXTBEFORE('周计划明细'!F12,":"),"") | D34: =IFERROR(VALUE(TEXTBEFORE(TEXTAFTER('周计划明细'!F12,"|"),"h")),0)
A35: 13 | B35: 上午 | C35: =IFERROR(TEXTBEFORE('周计划明细'!D13,":"),"") | D35: =IFERROR(VALUE(TEXTBEFORE(TEXTAFTER('周计划明细'!D13,"|"),"h")),0)
A36: 13 | B36: 下午 | C36: =IFERROR(TEXTBEFORE('周计划明细'!E13,":"),"") | D36: =IFERROR(VALUE(TEXTBEFORE(TEXTAFTER('周计划明细'!E13,"|"),"h")),0)
A37: 13 | B37: 晚上 | C37: =IFERROR(TEXTBEFORE('周计划明细'!F13,":"),"") | D37: =IFERROR(VALUE(TEXTBEFORE(TEXTAFTER('周计划明细'!F13,"|"),"h")),0)
A38: 14 | B38: 上午 | C38: =IFERROR(TEXTBEFORE('周计划明细'!D14,":"),"") | D38: =IFERROR(VALUE(TEXTBEFORE(TEXTAFTER('周计划明细'!D14,"|"),"h")),0)
A39: 14 | B39: 下午 | C39: =IFERROR(TEXTBEFORE('周计划明细'!E14,":"),"") | D39: =IFERROR(VALUE(TEXTBEFORE(TEXTAFTER('周计划明细'!E14,"|"),"h")),0)
A40: 14 | B40: 晚上 | C40: =IFERROR(TEXTBEFORE('周计划明细'!F14,":"),"") | D40: =IFERROR(VALUE(TEXTBEFORE(TEXTAFTER('周计划明细'!F14,"|"),"h")),0)
...
